Workbook

Sheet Methodology
B2: Exit Valuation Framework (built for Cedars-Sinai Technology Ventures, June 2026)
B3: SAMPLE FILE: every company, valuation, ownership stake, investment and comparable in this workbook is SYNTHETIC. The structure, formulas and stage ladder are the original model's.
B5: EXIT VALUE = COMPARABLES YOU SUPPLY
B6: Each company's exit value is built bottom-up from comparables. The company's engagement status with the hospital is excluded: it does not reflect market maturity and was skewing the data.
B8: TWO COMP TYPES, SHOWN SEPARATELY
B9: • EXIT comps (M&A / IPO of similar companies) - already an exit value. Median = the Exit-comp estimate.
B10: • PRIVATE comps (recent private valuations of peers) - current value, grown to exit via a step-up. Mean × step-up = the Private-comp estimate.
B11: Both estimates plus their average are displayed.
B13: THE FORMULA
B14: Expected exit value to us = P(exit) × Exit Value × FD Ownership at Exit (with the option to discount to PV)
B16: OWNERSHIP
B17: The math multiplies by the fund's fully diluted shareholding.
... B20: Probability uses a stage-based default, or a company-specific override (e.g. PitchBook exit predictor). Stage drives probability and timing only, not the exit value.

Sheet Summary
A1: Portfolio Summary
A2: Populates as comps and stages are filled in. Risk-adjusted = expected value.
A4: Estimated follow-on investment ( Model 2) | B4: ='Valuation Model 2'!AD45 -> 82042750
A5: Gross exit value (Average basis) | B5: =SUM('Valuation Model'!T3:T44) -> 3.7874422e+08
A6: Risk-adjusted (expected), Average basis | B6: =SUM('Valuation Model'!U3:U44) -> 1.917003e+08
A7: Total invested | B7: =SUM('Valuation Model'!Y3:Y44) -> 79962000
A8: Portfolio expected MOIC (probability-weighted, all companies) | B8: ='Valuation Model'!Z45 -> 2.3973925
A9: Portfolio expected MOIC (excluding realized exit, Company 33) | B9: =(B6-'Valuation Model'!U35)/(B7-'Valuation Model'!Y35) -> 2.2124362
A10: PV of risk-adjusted exit value | B10: =SUM('Valuation Model'!X3:X44) -> 1.2274612e+08
A11: Net expected MOIC incl. follow-on reserves (Model 2) | B11: ='Valuation Model 2'!AF45 -> 1.1833005
A12: Legacy method exit value (hardcoded multiple), for comparison | B12: =SUM('Valuation Model'!AA3:AA44) -> 425399298

Sheet Valuation Model
A1: Valuation Model
A2: Company | B2: Code | C2: Sector | D2: Stage | E2: Current Val internal ($) | F2: # Exit comps | G2: Exit Value using Exit comps ($) (Median) | H2: # Private comps | I2: Private peer val mean ($) | J2: Step-up to exit (x) | K2: Exit Value using Private comps ($) | L2: Exit Value ($) | M2: Fund FD Ownership (%) | N2: P: default | O2: P: override | P2: P: used | Q2: Exit Yr: default | R2: Exit Yr: override | S2: Exit Yr: used | T2: Gross exit to fund ($) | U2: Risk-Adj Average ($) | V2: Risk-Adj — Exit basis ($) | W2: Risk-Adj — Private basis ($) | X2: PV of Risk-Adj ($) | Y2: Total Invested ($) | Z2: Exp. MOIC | AA2: Legacy method exit ($) | AB2: Notes
A3: Company 01 | B3: PC-01 | C3: Bio tech | D3: S2 | E3: 15790000 | F3: =COUNTIFS(Comps!$A$3:$A$700,$A3,Comps!$C$3:$C$700,"Exit",Comps!$G$3:$G$700,"Y") -> 1 | G3: {=IFERROR(MEDIAN(IF((Comps!$A$3:$A$700=$A3)*(Comps!$C$3:$C$700="Exit")*(Comps!$G$3:$G$700="Y"),Comps!$D$3:$D$700)),0)} -> 38930000 | H3: =COUNTIFS(Comps!$A$3:$A$700,$A3,Comps!$C$3:$C$700,"Private",Comps!$G$3:$G$700,"Y") -> 4 | I3: =IFERROR(AVERAGEIFS(Comps!$D$3:$D$700,Comps!$A$3:$A$700,$A3,Comps!$C$3:$C$700,"Private",Comps!$G$3:$G$700,"Y"),0) -> 22752500 | J3: =Assumptions!$B$7 -> 2.5 | K3: =I3*J3 -> 56881250 | L3: =IF(AND(G3>0,K3>0),(G3+K3)/2,MAX(G3,K3)) -> 47905625 | M3: 0.0732 | N3: =IFERROR(INDEX(Assumptions!$D$11:$D$19,MATCH(D3,Assumptions!$A$11:$A$19,0)),0) -> 0.13 | P3: =IFERROR(IF(ISBLANK(O3),N3,O3),0) -> 0.13 | Q3: =IFERROR(Assumptions!$B$5+INDEX(Assumptions!$E$11:$E$19,MATCH(D3,Assumptions!$A$11:$A$19,0)),Assumptions!$B$5) -> 2033 | S3: =IF(ISBLANK(R3),Q3,R3) -> 2033 | T3: =L3*M3 -> 3506691.8 | U3: =P3*L3*M3 -> 455869.93 | V3: =P3*G3*M3 -> 370457.88 | W3: =P3*K3*M3 -> 541281.97 | X3: =IFERROR(U3/(1+Assumptions!$B$6)^(S3-Assumptions!$B$5),0) -> 171378.39 | Y3: 612000 | Z3: =IF(Y3=0,"",U3/Y3) -> 0.7448855 | AA3: =E3*Assumptions!$B$8*M3 -> 3467484 | AB3: Synthetic company. Stage S2.
A4: Company 02 | B4: PC-02 | C4: Bio tech | D4: D | E4: 0 | F4: =COUNTIFS(Comps!$A$3:$A$700,$A4,Comps!$C$3:$C$700,"Exit",Comps!$G$3:$G$700,"Y") -> 0 | G4: {=IFERROR(MEDIAN(IF((Comps!$A$3:$A$700=$A4)*(Comps!$C$3:$C$700="Exit")*(Comps!$G$3:$G$700="Y"),Comps!$D$3:$D$700)),0)} -> 0 | H4: =COUNTIFS(Comps!$A$3:$A$700,$A4,Comps!$C$3:$C$700,"Private",Comps!$G$3:$G$700,"Y") -> 0 | I4: =IFERROR(AVERAGEIFS(Comps!$D$3:$D$700,Comps!$A$3:$A$700,$A4,Comps!$C$3:$C$700,"Private",Comps!$G$3:$G$700,"Y"),0) -> 0 | J4: =Assumptions!$B$7 -> 2.5 | K4: =I4*J4 -> 0 | L4: =IF(AND(G4>0,K4>0),(G4+K4)/2,MAX(G4,K4)) -> 0 | M4: 0.0426 | N4: =IFERROR(INDEX(Assumptions!$D$11:$D$19,MATCH(D4,Assumptions!$A$11:$A$19,0)),0) -> 0.03 | P4: =IFERROR(IF(ISBLANK(O4),N4,O4),0) -> 0.03 | Q4: =IFERROR(Assumptions!$B$5+INDEX(Assumptions!$E$11:$E$19,MATCH(D4,Assumptions!$A$11:$A$19,0)),Assumptions!$B$5) -> 2027 | S4: =IF(ISBLANK(R4),Q4,R4) -> 2027 | T4: =L4*M4 -> 0 | U4: =P4*L4*M4 -> 0 | V4: =P4*G4*M4 -> 0 | W4: =P4*K4*M4 -> 0 | X4: =IFERROR(U4/(1+Assumptions!$B$6)^(S4-Assumptions!$B$5),0) -> 0 | Y4: 178000 | Z4: =IF(Y4=0,"",U4/Y4) -> 0 | AA4: =E4*Assumptions!$B$8*M4 -> 0 | AB4: Synthetic company. Stage D. Written down; no comps, stage default P(exit) applies to a nil value.
A5: Company 03 | B5: PC-03 | C5: Health Tech | D5: S4 | E5: 55490000 | F5: =COUNTIFS(Comps!$A$3:$A$700,$A5,Comps!$C$3:$C$700,"Exit",Comps!$G$3:$G$700,"Y") -> 5 | G5: {=IFERROR(MEDIAN(IF((Comps!$A$3:$A$700=$A5)*(Comps!$C$3:$C$700="Exit")*(Comps!$G$3:$G$700="Y"),Comps!$D$3:$D$700)),0)} -> 163660000 | H5: =COUNTIFS(Comps!$A$3:$A$700,$A5,Comps!$C$3:$C$700,"Private",Comps!$G$3:$G$700,"Y") -> 4 | I5: =IFERROR(AVERAGEIFS(Comps!$D$3:$D$700,Comps!$A$3:$A$700,$A5,Comps!$C$3:$C$700,"Private",Comps!$G$3:$G$700,"Y"),0) -> 62277500 | J5: =Assumptions!$B$7 -> 2.5 | K5: =I5*J5 -> 155693750 | L5: =IF(AND(G5>0,K5>0),(G5+K5)/2,MAX(G5,K5)) -> 159676875 | M5: 0.0779 | N5: =IFERROR(INDEX(Assumptions!$D$11:$D$19,MATCH(D5,Assumptions!$A$11:$A$19,0)),0) -> 0.3 | P5: =IFERROR(IF(ISBLANK(O5),N5,O5),0) -> 0.3 | Q5: =IFERROR(Assumptions!$B$5+INDEX(Assumptions!$E$11:$E$19,MATCH(D5,Assumptions!$A$11:$A$19,0)),Assumptions!$B$5) -> 2031 | S5: =IF(ISBLANK(R5),Q5,R5) -> 2031 | T5: =L5*M5 -> 12438829 | U5: =P5*L5*M5 -> 3731648.6 | V5: =P5*G5*M5 -> 3824734.2 | W5: =P5*K5*M5 -> 3638562.9 | X5: =IFERROR(U5/(1+Assumptions!$B$6)^(S5-Assumptions!$B$5),0) -> 1855288.9 | Y5: 3753000 | Z5: =IF(Y5=0,"",U5/Y5) -> 0.99431084 | AA5: =E5*Assumptions!$B$8*M5 -> 12968013 | AB5: Synthetic company. Stage S4.
A6: Company 04 | B6: PC-04 | C6: Health Tech | D6: S7 | E6: 21310000 | F6: =COUNTIFS(Comps!$A$3:$A$700,$A6,Comps!$C$3:$C$700,"Exit",Comps!$G$3:$G$700,"Y") -> 1 | G6: {=IFERROR(MEDIAN(IF((Comps!$A$3:$A$700=$A6)*(Comps!$C$3:$C$700="Exit")*(Comps!$G$3:$G$700="Y"),Comps!$D$3:$D$700)),0)} -> 29240000 | H6: =COUNTIFS(Comps!$A$3:$A$700,$A6,Comps!$C$3:$C$700,"Private",Comps!$G$3:$G$700,"Y") -> 2 | I6: =IFERROR(AVERAGEIFS(Comps!$D$3:$D$700,Comps!$A$3:$A$700,$A6,Comps!$C$3:$C$700,"Private",Comps!$G$3:$G$700,"Y"),0) -> 32275000 | J6: =Assumptions!$B$7 -> 2.5 | K6: =I6*J6 -> 80687500 | L6: =IF(AND(G6>0,K6>0),(G6+K6)/2,MAX(G6,K6)) -> 54963750 | M6: 0.1025 | N6: =IFERROR(INDEX(Assumptions!$D$11:$D$19,MATCH(D6,Assumptions!$A$11:$A$19,0)),0) -> 0.72 | P6: =IFERROR(IF(ISBLANK(O6),N6,O6),0) -> 0.72 | Q6: =IFERROR(Assumptions!$B$5+INDEX(Assumptions!$E$11:$E$19,MATCH(D6,Assumptions!$A$11:$A$19,0)),Assumptions!$B$5) -> 2028 | S6: =IF(ISBLANK(R6),Q6,R6) -> 2028 | T6: =L6*M6 -> 5633784.4 | U6: =P6*L6*M6 -> 4056324.8 | V6: =P6*G6*M6 -> 2157912 | W6: =P6*K6*M6 -> 5954737.5 | X6: =IFERROR(U6/(1+Assumptions!$B$6)^(S6-Assumptions!$B$5),0) -> 3067164.3 | Y6: 906000 | Z6: =IF(Y6=0,"",U6/Y6) -> 4.4771796 | AA6: =E6*Assumptions!$B$8*M6 -> 6552825 | AB6: Synthetic company. Stage S7.
A7: Company 05 | B7: PC-05 | C7: Bio tech | D7: S7 | E7: 36460000 | F7: =COUNTIFS(Comps!$A$3:$A$700,$A7,Comps!$C$3:$C$700,"Exit",Comps!$G$3:$G$700,"Y") -> 2 | G7: {=IFERROR(MEDIAN(IF((Comps!$A$3:$A$700=$A7)*(Comps!$C$3:$C$700="Exit")*(Comps!$G$3:$G$700="Y"),Comps!$D$3:$D$700)),0)} -> 62685000 | H7: =COUNTIFS(Comps!$A$3:$A$700,$A7,Comps!$C$3:$C$700,"Private",Comps!$G$3:$G$700,"Y") -> 2 | I7: =IFERROR(AVERAGEIFS(Comps!$D$3:$D$700,Comps!$A$3:$A$700,$A7,Comps!$C$3:$C$700,"Private",Comps!$G$3:$G$700,"Y"),0) -> 115875000 | J7: 1 | K7: =I7*J7 -> 115875000 | L7: =IF(AND(G7>0,K7>0),(G7+K7)/2,MAX(G7,K7)) -> 89280000 | M7: 0.0698 | N7: =IFERROR(INDEX(Assumptions!$D$11:$D$19,MATCH(D7,Assumptions!$A$11:$A$19,0)),0) -> 0.72 | P7: =IFERROR(IF(ISBLANK(O7),N7,O7),0) -> 0.72 | Q7: =IFERROR(Assumptions!$B$5+INDEX(Assumptions!$E$11:$E$19,MATCH(D7,Assumptions!$A$11:$A$19,0)),Assumptions!$B$5) -> 2028 | S7: =IF(ISBLANK(R7),Q7,R7) -> 2028 | T7: =L7*M7 -> 6231744 | U7: =P7*L7*M7 -> 4486855.7 | V7: =P7*G7*M7 -> 3150297.4 | W7: =P7*K7*M7 -> 5823414 | X7: =IFERROR(U7/(1+Assumptions!$B$6)^(S7-Assumptions!$B$5),0) -> 3392707.5 | Y7: 1337000 | Z7: =IF(Y7=0,"",U7/Y7) -> 3.355913 | AA7: =E7*Assumptions!$B$8*M7 -> 7634724 | AB7: Synthetic company. Stage S7. Private step-up set to 1.0x: peers already at exit-scale valuations.
A8: Company 06 | B8: PC-06 | C8: Health Tech | D8: S2 | E8: 59680000 | F8: =COUNTIFS(Comps!$A$3:$A$700,$A8,Comps!$C$3:$C$700,"Exit",Comps!$G$3:$G$700,"Y") -> 1 | G8: {=IFERROR(MEDIAN(IF((Comps!$A$3:$A$700=$A8)*(Comps!$C$3:$C$700="Exit")*(Comps!$G$3:$G$700="Y"),Comps!$D$3:$D$700)),0)} -> 378280000 | H8: =COUNTIFS(Comps!$A$3:$A$700,$A8,Comps!$C$3:$C$700,"Private",Comps!$G$3:$G$700,"Y") -> 1 | I8: =IFERROR(AVERAGEIFS(Comps!$D$3:$D$700,Comps!$A$3:$A$700,$A8,Comps!$C$3:$C$700,"Private",Comps!$G$3:$G$700,"Y"),0) -> 45840000 | J8: =Assumptions!$B$7 -> 2.5 | K8: =I8*J8 -> 114600000 | L8: =IF(AND(G8>0,K8>0),(G8+K8)/2,MAX(G8,K8)) -> 246440000 | M8: 0.0315 | N8: =IFERROR(INDEX(Assumptions!$D$11:$D$19,MATCH(D8,Assumptions!$A$11:$A$19,0)),0) -> 0.13 | P8: =IFERROR(IF(ISBLANK(O8),N8,O8),0) -> 0.13 | Q8: =IFERROR(Assumptions!$B$5+INDEX(Assumptions!$E$11:$E$19,MATCH(D8,Assumptions!$A$11:$A$19,0)),Assumptions!$B$5) -> 2033 | S8: =IF(ISBLANK(R8),Q8,R8) -> 2033 | T8: =L8*M8 -> 7762860 | U8: =P8*L8*M8 -> 1009171.8 | V8: =P8*G8*M8 -> 1549056.6 | W8: =P8*K8*M8 -> 469287 | X8: =IFERROR(U8/(1+Assumptions!$B$6)^(S8-Assumptions!$B$5),0) -> 379385.06 | Y8: 1648000 | Z8: =IF(Y8=0,"",U8/Y8) -> 0.61236153 | AA8: =E8*Assumptions!$B$8*M8 -> 5639760 | AB8: Synthetic company. Stage S2.
A9: Company 07 | B9: PC-07 | C9: Med tech | D9: S4 | E9: 38110000 | F9: =COUNTIFS(Comps!$A$3:$A$700,$A9,Comps!$C$3:$C$700,"Exit",Comps!$G$3:$G$700,"Y") -> 6 | G9: {=IFERROR(MEDIAN(IF((Comps!$A$3:$A$700=$A9)*(Comps!$C$3:$C$700="Exit")*(Comps!$G$3:$G$700="Y"),Comps!$D$3:$D$700)),0)} -> 101400000 | H9: =COUNTIFS(Comps!$A$3:$A$700,$A9,Comps!$C$3:$C$700,"Private",Comps!$G$3:$G$700,"Y") -> 0 | I9: =IFERROR(AVERAGEIFS(Comps!$D$3:$D$700,Comps!$A$3:$A$700,$A9,Comps!$C$3:$C$700,"Private",Comps!$G$3:$G$700,"Y"),0) -> 0 | J9: =Assumptions!$B$7 -> 2.5 | K9: =I9*J9 -> 0 | L9: =IF(AND(G9>0,K9>0),(G9+K9)/2,MAX(G9,K9)) -> 101400000 | M9: 0.1034 | N9: =IFERROR(INDEX(Assumptions!$D$11:$D$19,MATCH(D9,Assumptions!$A$11:$A$19,0)),0) -> 0.3 | P9: =IFERROR(IF(ISBLANK(O9),N9,O9),0) -> 0.3 | Q9: =IFERROR(Assumptions!$B$5+INDEX(Assumptions!$E$11:$E$19,MATCH(D9,Assumptions!$A$11:$A$19,0)),Assumptions!$B$5) -> 2031 | S9: =IF(ISBLANK(R9),Q9,R9) -> 2031 | T9: =L9*M9 -> 10484760 | U9: =P9*L9*M9 -> 3145428 | V9: =P9*G9*M9 -> 3145428 | W9: =P9*K9*M9 -> 0 | X9: =IFERROR(U9/(1+Assumptions!$B$6)^(S9-Assumptions!$B$5),0) -> 1563833.6 | Y9: 3051000 | Z9: =IF(Y9=0,"",U9/Y9) -> 1.0309499 | AA9: =E9*Assumptions!$B$8*M9 -> 11821722 | AB9: Synthetic company. Stage S4.
A10: Company 08 | B10: PC-08 | C10: Bio tech | D10: S7 | E10: 17410000 | F10: =COUNTIFS(Comps!$A$3:$A$700,$A10,Comps!$C$3:$C$700,"Exit",Comps!$G$3:$G$700,"Y") -> 4 | G10: {=IFERROR(MEDIAN(IF((Comps!$A$3:$A$700=$A10)*(Comps!$C$3:$C$700="Exit")*(Comps!$G$3:$G$700="Y"),Comps!$D$3:$D$700)),0)} -> 21725000 | H10: =COUNTIFS(Comps!$A$3:$A$700,$A10,Comps!$C$3:$C$700,"Private",Comps!$G$3:$G$700,"Y") -> 2 | I10: =IFERROR(AVERAGEIFS(Comps!$D$3:$D$700,Comps!$A$3:$A$700,$A10,Comps!$C$3:$C$700,"Private",Comps!$G$3:$G$700,"Y"),0) -> 20785000 | J10: =Assumptions!$B$7 -> 2.5 | K10: =I10*J10 -> 51962500 | L10: =IF(AND(G10>0,K10>0),(G10+K10)/2,MAX(G10,K10)) -> 36843750 | M10: 0.0277 | N10: =IFERROR(INDEX(Assumptions!$D$11:$D$19,MATCH(D10,Assumptions!$A$11:$A$19,0)),0) -> 0.72 | O10: 0.39 | P10: =IFERROR(IF(ISBLANK(O10),N10,O10),0) -> 0.39 | Q10: =IFERROR(Assumptions!$B$5+INDEX(Assumptions!$E$11:$E$19,MATCH(D10,Assumptions!$A$11:$A$19,0)),Assumptions!$B$5) -> 2028 | S10: =IF(ISBLANK(R10),Q10,R10) -> 2028 | T10: =L10*M10 -> 1020571.9 | U10: =P10*L10*M10 -> 398023.03 | V10: =P10*G10*M10 -> 234695.17 | W10: =P10*K10*M10 -> 561350.89 | X10: =IFERROR(U10/(1+Assumptions!$B$6)^(S10-Assumptions!$B$5),0) -> 300962.59 | Y10: 267000 | Z10: =IF(Y10=0,"",U10/Y10) -> 1.490723 | AA10: =E10*Assumptions!$B$8*M10 -> 1446771 | AB10: Synthetic company. Stage S7. P(exit) overridden to 39% (exit-predictor style input).
A11: Company 09 | B11: PC-09 | C11: Health Tech | D11: S4 | E11: 42870000 | F11: =COUNTIFS(Comps!$A$3:$A$700,$A11,Comps!$C$3:$C$700,"Exit",Comps!$G$3:$G$700,"Y") -> 1 | G11: {=IFERROR(MEDIAN(IF((Comps!$A$3:$A$700=$A11)*(Comps!$C$3:$C$700="Exit")*(Comps!$G$3:$G$700="Y"),Comps!$D$3:$D$700)),0)} -> 44590000 | H11: =COUNTIFS(Comps!$A$3:$A$700,$A11,Comps!$C$3:$C$700,"Private",Comps!$G$3:$G$700,"Y") -> 0 | I11: =IFERROR(AVERAGEIFS(Comps!$D$3:$D$700,Comps!$A$3:$A$700,$A11,Comps!$C$3:$C$700,"Private",Comps!$G$3:$G$700,"Y"),0) -> 0 | J11: =Assumptions!$B$7 -> 2.5 | K11: =I11*J11 -> 0 | L11: =IF(AND(G11>0,K11>0),(G11+K11)/2,MAX(G11,K11)) -> 44590000 | M11: 0.0497 | N11: =IFERROR(INDEX(Assumptions!$D$11:$D$19,MATCH(D11,Assumptions!$A$11:$A$19,0)),0) -> 0.3 | P11: =IFERROR(IF(ISBLANK(O11),N11,O11),0) -> 0.3 | Q11: =IFERROR(Assumptions!$B$5+INDEX(Assumptions!$E$11:$E$19,MATCH(D11,Assumptions!$A$11:$A$19,0)),Assumptions!$B$5) -> 2031 | S11: =IF(ISBLANK(R11),Q11,R11) -> 2031 | T11: =L11*M11 -> 2216123 | U11: =P11*L11*M11 -> 664836.9 | V11: =P11*G11*M11 -> 664836.9 | W11: =P11*K11*M11 -> 0 | X11: =IFERROR(U11/(1+Assumptions!$B$6)^(S11-Assumptions!$B$5),0) -> 330541.44 | Y11: 1772000 | Z11: =IF(Y11=0,"",U11/Y11) -> 0.37519012 | AA11: =E11*Assumptions!$B$8*M11 -> 6391917 | AB11: Synthetic company. Stage S4.
A12: Company 10 | B12: PC-10 | C12: Health Tech | D12: S2 | E12: 16920000 | F12: =COUNTIFS(Comps!$A$3:$A$700,$A12,Comps!$C$3:$C$700,"Exit",Comps!$G$3:$G$700,"Y") -> 7 | G12: {=IFERROR(MEDIAN(IF((Comps!$A$3:$A$700=$A12)*(Comps!$C$3:$C$700="Exit")*(Comps!$G$3:$G$700="Y"),Comps!$D$3:$D$700)),0)} -> 130310000 | H12: =COUNTIFS(Comps!$A$3:$A$700,$A12,Comps!$C$3:$C$700,"Private",Comps!$G$3:$G$700,"Y") -> 1 | I12: =IFERROR(AVERAGEIFS(Comps!$D$3:$D$700,Comps!$A$3:$A$700,$A12,Comps!$C$3:$C$700,"Private",Comps!$G$3:$G$700,"Y"),0) -> 19120000 | J12: =Assumptions!$B$7 -> 2.5 | K12: =I12*J12 -> 47800000 | L12: =IF(AND(G12>0,K12>0),(G12+K12)/2,MAX(G12,K12)) -> 89055000 | M12: 0.0424 | N12: =IFERROR(INDEX(Assumptions!$D$11:$D$19,MATCH(D12,Assumptions!$A$11:$A$19,0)),0) -> 0.13 | O12: 0.29 | P12: =IFERROR(IF(ISBLANK(O12),N12,O12),0) -> 0.29 | Q12: =IFERROR(Assumptions!$B$5+INDEX(Assumptions!$E$11:$E$19,MATCH(D12,Assumptions!$A$11:$A$19,0)),Assumptions!$B$5) -> 2033 | S12: =IF(ISBLANK(R12),Q12,R12) -> 2033 | T12: =L12*M12 -> 3775932 | U12: =P12*L12*M12 -> 1095020.3 | V12: =P12*G12*M12 -> 1602291.8 | W12: =P12*K12*M12 -> 587748.8 | X12: =IFERROR(U12/(1+Assumptions!$B$6)^(S12-Assumptions!$B$5),0) -> 411658.68 | Y12: 610000 | Z12: =IF(Y12=0,"",U12/Y12) -> 1.7951152 | AA12: =E12*Assumptions!$B$8*M12 -> 2152224 | AB12: Synthetic company. Stage S2. P(exit) overridden to 29% (exit-predictor style input).
A13: Company 11 | B13: PC-11 | C13: Bio tech | D13: S7 | E13: 74430000 | F13: =COUNTIFS(Comps!$A$3:$A$700,$A13,Comps!$C$3:$C$700,"Exit",Comps!$G$3:$G$700,"Y") -> 2 | G13: {=IFERROR(MEDIAN(IF((Comps!$A$3:$A$700=$A13)*(Comps!$C$3:$C$700="Exit")*(Comps!$G$3:$G$700="Y"),Comps!$D$3:$D$700)),0)} -> 145940000 | H13: =COUNTIFS(Comps!$A$3:$A$700,$A13,Comps!$C$3:$C$700,"Private",Comps!$G$3:$G$700,"Y") -> 4 | I13: =IFERROR(AVERAGEIFS(Comps!$D$3:$D$700,Comps!$A$3:$A$700,$A13,Comps!$C$3:$C$700,"Private",Comps!$G$3:$G$700,"Y"),0) -> 87067500 | J13: =Assumptions!$B$7 -> 2.5 | K13: =I13*J13 -> 217668750 | L13: =IF(AND(G13>0,K13>0),(G13+K13)/2,MAX(G13,K13)) -> 181804375 | M13: 0.0555 | N13: =IFERROR(INDEX(Assumptions!$D$11:$D$19,MATCH(D13,Assumptions!$A$11:$A$19,0)),0) -> 0.72 | O13: 0.29 | P13: =IFERROR(IF(ISBLANK(O13),N13,O13),0) -> 0.29 | Q13: =IFERROR(Assumptions!$B$5+INDEX(Assumptions!$E$11:$E$19,MATCH(D13,Assumptions!$A$11:$A$19,0)),Assumptions!$B$5) -> 2028 | S13: =IF(ISBLANK(R13),Q13,R13) -> 2028 | T13: =L13*M13 -> 10090143 | U13: =P13*L13*M13 -> 2926141.4 | V13: =P13*G13*M13 -> 2348904.3 | W13: =P13*K13*M13 -> 3503378.5 | X13: =IFERROR(U13/(1+Assumptions!$B$6)^(S13-Assumptions!$B$5),0) -> 2212583.3 | Y13: 3144000 | Z13: =IF(Y13=0,"",U13/Y13) -> 0.93070656 | AA13: =E13*Assumptions!$B$8*M13 -> 12392595 | AB13: Synthetic company. Stage S7. P(exit) overridden to 29% (exit-predictor style input).
A14: Company 12 | B14: PC-12 | C14: Bio tech | D14: S4 | E14: 51790000 | F14: =COUNTIFS(Comps!$A$3:$A$700,$A14,Comps!$C$3:$C$700,"Exit",Comps!$G$3:$G$700,"Y") -> 8 | G14: {=IFERROR(MEDIAN(IF((Comps!$A$3:$A$700=$A14)*(Comps!$C$3:$C$700="Exit")*(Comps!$G$3:$G$700="Y"),Comps!$D$3:$D$700)),0)} -> 109045000 | H14: =COUNTIFS(Comps!$A$3:$A$700,$A14,Comps!$C$3:$C$700,"Private",Comps!$G$3:$G$700,"Y") -> 2 | I14: =IFERROR(AVERAGEIFS(Comps!$D$3:$D$700,Comps!$A$3:$A$700,$A14,Comps!$C$3:$C$700,"Private",Comps!$G$3:$G$700,"Y"),0) -> 46105000 | J14: =Assumptions!$B$7 -> 2.5 | K14: =I14*J14 -> 115262500 | L14: =IF(AND(G14>0,K14>0),(G14+K14)/2,MAX(G14,K14)) -> 112153750 | M14: 0.0819 | N14: =IFERROR(INDEX(Assumptions!$D$11:$D$19,MATCH(D14,Assumptions!$A$11:$A$19,0)),0) -> 0.3 | P14: =IFERROR(IF(ISBLANK(O14),N14,O14),0) -> 0.3 | Q14: =IFERROR(Assumptions!$B$5+INDEX(Assumptions!$E$11:$E$19,MATCH(D14,Assumptions!$A$11:$A$19,0)),Assumptions!$B$5) -> 2031 | S14: =IF(ISBLANK(R14),Q14,R14) -> 2031 | T14: =L14*M14 -> 9185392.1 | U14: =P14*L14*M14 -> 2755617.6 | V14: =P14*G14*M14 -> 2679235.6 | W14: =P14*K14*M14 -> 2831999.6 | X14: =IFERROR(U14/(1+Assumptions!$B$6)^(S14-Assumptions!$B$5),0) -> 1370029 | Y14: 1874000 | Z14: =IF(Y14=0,"",U14/Y14) -> 1.470447 | AA14: =E14*Assumptions!$B$8*M14 -> 12724803 | AB14: Synthetic company. Stage S4.
A15: Company 13 | B15: PC-13 | C15: Health Tech | D15: S2 | E15: 27080000 | F15: =COUNTIFS(Comps!$A$3:$A$700,$A15,Comps!$C$3:$C$700,"Exit",Comps!$G$3:$G$700,"Y") -> 3 | G15: {=IFERROR(MEDIAN(IF((Comps!$A$3:$A$700=$A15)*(Comps!$C$3:$C$700="Exit")*(Comps!$G$3:$G$700="Y"),Comps!$D$3:$D$700)),0)} -> 105990000 | H15: =COUNTIFS(Comps!$A$3:$A$700,$A15,Comps!$C$3:$C$700,"Private",Comps!$G$3:$G$700,"Y") -> 1 | I15: =IFERROR(AVERAGEIFS(Comps!$D$3:$D$700,Comps!$A$3:$A$700,$A15,Comps!$C$3:$C$700,"Private",Comps!$G$3:$G$700,"Y"),0) -> 44500000 | J15: =Assumptions!$B$7 -> 2.5 | K15: =I15*J15 -> 111250000 | L15: =IF(AND(G15>0,K15>0),(G15+K15)/2,MAX(G15,K15)) -> 108620000 | M15: 0.0609 | N15: =IFERROR(INDEX(Assumptions!$D$11:$D$19,MATCH(D15,Assumptions!$A$11:$A$19,0)),0) -> 0.13 | P15: =IFERROR(IF(ISBLANK(O15),N15,O15),0) -> 0.13 | Q15: =IFERROR(Assumptions!$B$5+INDEX(Assumptions!$E$11:$E$19,MATCH(D15,Assumptions!$A$11:$A$19,0)),Assumptions!$B$5) -> 2033 | S15: =IF(ISBLANK(R15),Q15,R15) -> 2033 | T15: =L15*M15 -> 6614958 | U15: =P15*L15*M15 -> 859944.54 | V15: =P15*G15*M15 -> 839122.83 | W15: =P15*K15*M15 -> 880766.25 | X15: =IFERROR(U15/(1+Assumptions!$B$6)^(S15-Assumptions!$B$5),0) -> 323285 | Y15: 1156000 | Z15: =IF(Y15=0,"",U15/Y15) -> 0.74389666 | AA15: =E15*Assumptions!$B$8*M15 -> 4947516 | AB15: Synthetic company. Stage S2.
A16: Company 14 | B16: PC-14 | C16: Med tech | D16: S7 | E16: 17580000 | F16: =COUNTIFS(Comps!$A$3:$A$700,$A16,Comps!$C$3:$C$700,"Exit",Comps!$G$3:$G$700,"Y") -> 5 | G16: {=IFERROR(MEDIAN(IF((Comps!$A$3:$A$700=$A16)*(Comps!$C$3:$C$700="Exit")*(Comps!$G$3:$G$700="Y"),Comps!$D$3:$D$700)),0)} -> 39550000 | H16: =COUNTIFS(Comps!$A$3:$A$700,$A16,Comps!$C$3:$C$700,"Private",Comps!$G$3:$G$700,"Y") -> 1 | I16: =IFERROR(AVERAGEIFS(Comps!$D$3:$D$700,Comps!$A$3:$A$700,$A16,Comps!$C$3:$C$700,"Private",Comps!$G$3:$G$700,"Y"),0) -> 25020000 | J16: =Assumptions!$B$7 -> 2.5 | K16: =I16*J16 -> 62550000 | L16: =IF(AND(G16>0,K16>0),(G16+K16)/2,MAX(G16,K16)) -> 51050000 | M16: 0.0276 | N16: =IFERROR(INDEX(Assumptions!$D$11:$D$19,MATCH(D16,Assumptions!$A$11:$A$19,0)),0) -> 0.72 | P16: =IFERROR(IF(ISBLANK(O16),N16,O16),0) -> 0.72 | Q16: =IFERROR(Assumptions!$B$5+INDEX(Assumptions!$E$11:$E$19,MATCH(D16,Assumptions!$A$11:$A$19,0)),Assumptions!$B$5) -> 2028 | S16: =IF(ISBLANK(R16),Q16,R16) -> 2028 | T16: =L16*M16 -> 1408980 | U16: =P16*L16*M16 -> 1014465.6 | V16: =P16*G16*M16 -> 785937.6 | W16: =P16*K16*M16 -> 1242993.6 | X16: =IFERROR(U16/(1+Assumptions!$B$6)^(S16-Assumptions!$B$5),0) -> 767081.74 | Y16: 171000 | Z16: =IF(Y16=0,"",U16/Y16) -> 5.9325474 | AA16: =E16*Assumptions!$B$8*M16 -> 1455624 | AB16: Synthetic company. Stage S7.
A17: Company 15 | B17: PC-15 | C17: Bio tech | D17: S7 | E17: 23310000 | F17: =COUNTIFS(Comps!$A$3:$A$700,$A17,Comps!$C$3:$C$700,"Exit",Comps!$G$3:$G$700,"Y") -> 2 | G17: {=IFERROR(MEDIAN(IF((Comps!$A$3:$A$700=$A17)*(Comps!$C$3:$C$700="Exit")*(Comps!$G$3:$G$700="Y"),Comps!$D$3:$D$700)),0)} -> 21290000 | H17: =COUNTIFS(Comps!$A$3:$A$700,$A17,Comps!$C$3:$C$700,"Private",Comps!$G$3:$G$700,"Y") -> 0 | I17: =IFERROR(AVERAGEIFS(Comps!$D$3:$D$700,Comps!$A$3:$A$700,$A17,Comps!$C$3:$C$700,"Private",Comps!$G$3:$G$700,"Y"),0) -> 0 | J17: =Assumptions!$B$7 -> 2.5 | K17: =I17*J17 -> 0 | L17: =IF(AND(G17>0,K17>0),(G17+K17)/2,MAX(G17,K17)) -> 21290000 | M17: 0.0783 | N17: =IFERROR(INDEX(Assumptions!$D$11:$D$19,MATCH(D17,Assumptions!$A$11:$A$19,0)),0) -> 0.72 | O17: 0.53 | P17: =IFERROR(IF(ISBLANK(O17),N17,O17),0) -> 0.53 | Q17: =IFERROR(Assumptions!$B$5+INDEX(Assumptions!$E$11:$E$19,MATCH(D17,Assumptions!$A$11:$A$19,0)),Assumptions!$B$5) -> 2028 | S17: =IF(ISBLANK(R17),Q17,R17) -> 2028 | T17: =L17*M17 -> 1667007 | U17: =P17*L17*M17 -> 883513.71 | V17: =P17*G17*M17 -> 883513.71 | W17: =P17*K17*M17 -> 0 | X17: =IFERROR(U17/(1+Assumptions!$B$6)^(S17-Assumptions!$B$5),0) -> 668063.3 | Y17: 971000 | Z17: =IF(Y17=0,"",U17/Y17) -> 0.90990083 | AA17: =E17*Assumptions!$B$8*M17 -> 5475519 | AB17: Synthetic company. Stage S7. P(exit) overridden to 53% (exit-predictor style input).
A18: Company 16 | B18: PC-16 | C18: Bio tech | D18: S7 | E18: 17000000 | F18: =COUNTIFS(Comps!$A$3:$A$700,$A18,Comps!$C$3:$C$700,"Exit",Comps!$G$3:$G$700,"Y") -> 2 | G18: {=IFERROR(MEDIAN(IF((Comps!$A$3:$A$700=$A18)*(Comps!$C$3:$C$700="Exit")*(Comps!$G$3:$G$700="Y"),Comps!$D$3:$D$700)),0)} -> 48485000 | H18: =COUNTIFS(Comps!$A$3:$A$700,$A18,Comps!$C$3:$C$700,"Private",Comps!$G$3:$G$700,"Y") -> 2 | I18: =IFERROR(AVERAGEIFS(Comps!$D$3:$D$700,Comps!$A$3:$A$700,$A18,Comps!$C$3:$C$700,"Private",Comps!$G$3:$G$700,"Y"),0) -> 17180000 | J18: 1 | K18: =I18*J18 -> 17180000 | L18: =IF(AND(G18>0,K18>0),(G18+K18)/2,MAX(G18,K18)) -> 32832500 | M18: 0.0379 | N18: =IFERROR(INDEX(Assumptions!$D$11:$D$19,MATCH(D18,Assumptions!$A$11:$A$19,0)),0) -> 0.72 | O18: 0.38 | P18: =IFERROR(IF(ISBLANK(O18),N18,O18),0) -> 0.38 | Q18: =IFERROR(Assumptions!$B$5+INDEX(Assumptions!$E$11:$E$19,MATCH(D18,Assumptions!$A$11:$A$19,0)),Assumptions!$B$5) -> 2028 | S18: =IF(ISBLANK(R18),Q18,R18) -> 2028 | T18: =L18*M18 -> 1244351.8 | U18: =P18*L18*M18 -> 472853.66 | V18: =P18*G18*M18 -> 698280.97 | W18: =P18*K18*M18 -> 247426.36 | X18: =IFERROR(U18/(1+Assumptions!$B$6)^(S18-Assumptions!$B$5),0) -> 357545.3 | Y18: 539000 | Z18: =IF(Y18=0,"",U18/Y18) -> 0.87727953 | AA18: =E18*Assumptions!$B$8*M18 -> 1932900 | AB18: Synthetic company. Stage S7. P(exit) overridden to 38% (exit-predictor style input). Private step-up set to 1.0x: peers already at exit-scale valuations.
A19: Company 17 | B19: PC-17 | C19: Med tech | D19: S1 | E19: 6480000 | F19: =COUNTIFS(Comps!$A$3:$A$700,$A19,Comps!$C$3:$C$700,"Exit",Comps!$G$3:$G$700,"Y") -> 4 | G19: {=IFERROR(MEDIAN(IF((Comps!$A$3:$A$700=$A19)*(Comps!$C$3:$C$700="Exit")*(Comps!$G$3:$G$700="Y"),Comps!$D$3:$D$700)),0)} -> 19985000 | H19: =COUNTIFS(Comps!$A$3:$A$700,$A19,Comps!$C$3:$C$700,"Private",Comps!$G$3:$G$700,"Y") -> 1 | I19: =IFERROR(AVERAGEIFS(Comps!$D$3:$D$700,Comps!$A$3:$A$700,$A19,Comps!$C$3:$C$700,"Private",Comps!$G$3:$G$700,"Y"),0) -> 7280000 | J19: =Assumptions!$B$7 -> 2.5 | K19: =I19*J19 -> 18200000 | L19: =IF(AND(G19>0,K19>0),(G19+K19)/2,MAX(G19,K19)) -> 19092500 | M19: 0.0748 | N19: =IFERROR(INDEX(Assumptions!$D$11:$D$19,MATCH(D19,Assumptions!$A$11:$A$19,0)),0) -> 0.08 | O19: 0.58 | P19: =IFERROR(IF(ISBLANK(O19),N19,O19),0) -> 0.58 | Q19: =IFERROR(Assumptions!$B$5+INDEX(Assumptions!$E$11:$E$19,MATCH(D19,Assumptions!$A$11:$A$19,0)),Assumptions!$B$5) -> 2035 | S19: =IF(ISBLANK(R19),Q19,R19) -> 2035 | T19: =L19*M19 -> 1428119 | U19: =P19*L19*M19 -> 828309.02 | V19: =P19*G19*M19 -> 867029.24 | W19: =P19*K19*M19 -> 789588.8 | X19: =IFERROR(U19/(1+Assumptions!$B$6)^(S19-Assumptions!$B$5),0) -> 235457.12 | Y19: 251000 | Z19: =IF(Y19=0,"",U19/Y19) -> 3.3000359 | AA19: =E19*Assumptions!$B$8*M19 -> 1454112 | AB19: Synthetic company. Stage S1. P(exit) overridden to 58% (exit-predictor style input).
A20: Company 18 | B20: PC-18 | C20: Bio tech | D20: S7 | E20: 58820000 | F20: =COUNTIFS(Comps!$A$3:$A$700,$A20,Comps!$C$3:$C$700,"Exit",Comps!$G$3:$G$700,"Y") -> 6 | G20: {=IFERROR(MEDIAN(IF((Comps!$A$3:$A$700=$A20)*(Comps!$C$3:$C$700="Exit")*(Comps!$G$3:$G$700="Y"),Comps!$D$3:$D$700)),0)} -> 94090000 | H20: =COUNTIFS(Comps!$A$3:$A$700,$A20,Comps!$C$3:$C$700,"Private",Comps!$G$3:$G$700,"Y") -> 3 | I20: =IFERROR(AVERAGEIFS(Comps!$D$3:$D$700,Comps!$A$3:$A$700,$A20,Comps!$C$3:$C$700,"Private",Comps!$G$3:$G$700,"Y"),0) -> 30966667 | J20: 1 | K20: =I20*J20 -> 30966667 | L20: =IF(AND(G20>0,K20>0),(G20+K20)/2,MAX(G20,K20)) -> 62528333 | M20: 0.0509 | N20: =IFERROR(INDEX(Assumptions!$D$11:$D$19,MATCH(D20,Assumptions!$A$11:$A$19,0)),0) -> 0.72 | P20: =IFERROR(IF(ISBLANK(O20),N20,O20),0) -> 0.72 | Q20: =IFERROR(Assumptions!$B$5+INDEX(Assumptions!$E$11:$E$19,MATCH(D20,Assumptions!$A$11:$A$19,0)),Assumptions!$B$5) -> 2028 | S20: =IF(ISBLANK(R20),Q20,R20) -> 2028 | T20: =L20*M20 -> 3182692.2 | U20: =P20*L20*M20 -> 2291538.4 | V20: =P20*G20*M20 -> 3448210.3 | W20: =P20*K20*M20 -> 1134866.4 | X20: =IFERROR(U20/(1+Assumptions!$B$6)^(S20-Assumptions!$B$5),0) -> 1732732.2 | Y20: 2443000 | Z20: =IF(Y20=0,"",U20/Y20) -> 0.93800178 | AA20: =E20*Assumptions!$B$8*M20 -> 8981814 | AB20: Synthetic company. Stage S7. Private step-up set to 1.0x: peers already at exit-scale valuations.
A21: Company 19 | B21: PC-19 | C21: Med tech | D21: S7 | E21: 133030000 | F21: =COUNTIFS(Comps!$A$3:$A$700,$A21,Comps!$C$3:$C$700,"Exit",Comps!$G$3:$G$700,"Y") -> 3 | G21: {=IFERROR(MEDIAN(IF((Comps!$A$3:$A$700=$A21)*(Comps!$C$3:$C$700="Exit")*(Comps!$G$3:$G$700="Y"),Comps!$D$3:$D$700)),0)} -> 309380000 | H21: =COUNTIFS(Comps!$A$3:$A$700,$A21,Comps!$C$3:$C$700,"Private",Comps!$G$3:$G$700,"Y") -> 3 | I21: =IFERROR(AVERAGEIFS(Comps!$D$3:$D$700,Comps!$A$3:$A$700,$A21,Comps!$C$3:$C$700,"Private",Comps!$G$3:$G$700,"Y"),0) -> 1.6198667e+08 | J21: 1 | K21: =I21*J21 -> 1.6198667e+08 | L21: =IF(AND(G21>0,K21>0),(G21+K21)/2,MAX(G21,K21)) -> 2.3568333e+08 | M21: 0.0847 | N21: =IFERROR(INDEX(Assumptions!$D$11:$D$19,MATCH(D21,Assumptions!$A$11:$A$19,0)),0) -> 0.72 | O21: 0.9 | P21: =IFERROR(IF(ISBLANK(O21),N21,O21),0) -> 0.9 | Q21: =IFERROR(Assumptions!$B$5+INDEX(Assumptions!$E$11:$E$19,MATCH(D21,Assumptions!$A$11:$A$19,0)),Assumptions!$B$5) -> 2028 | S21: =IF(ISBLANK(R21),Q21,R21) -> 2028 | T21: =L21*M21 -> 19962378 | U21: =P21*L21*M21 -> 17966140 | V21: =P21*G21*M21 -> 23584037 | W21: =P21*K21*M21 -> 12348244 | X21: =IFERROR(U21/(1+Assumptions!$B$6)^(S21-Assumptions!$B$5),0) -> 13584983 | Y21: 7594000 | Z21: =IF(Y21=0,"",U21/Y21) -> 2.3658336 | AA21: =E21*Assumptions!$B$8*M21 -> 33802923 | AB21: Synthetic company. Stage S7. P(exit) overridden to 90% (exit-predictor style input). Private step-up set to 1.0x: peers already at exit-scale valuations.
A22: Company 20 | B22: PC-20 | C22: Med tech | D22: S5 | E22: 27970000 | F22: =COUNTIFS(Comps!$A$3:$A$700,$A22,Comps!$C$3:$C$700,"Exit",Comps!$G$3:$G$700,"Y") -> 1 | G22: {=IFERROR(MEDIAN(IF((Comps!$A$3:$A$700=$A22)*(Comps!$C$3:$C$700="Exit")*(Comps!$G$3:$G$700="Y"),Comps!$D$3:$D$700)),0)} -> 113970000 | H22: =COUNTIFS(Comps!$A$3:$A$700,$A22,Comps!$C$3:$C$700,"Private",Comps!$G$3:$G$700,"Y") -> 3 | I22: =IFERROR(AVERAGEIFS(Comps!$D$3:$D$700,Comps!$A$3:$A$700,$A22,Comps!$C$3:$C$700,"Private",Comps!$G$3:$G$700,"Y"),0) -> 33393333 | J22: =Assumptions!$B$7 -> 2.5 | K22: =I22*J22 -> 83483333 | L22: =IF(AND(G22>0,K22>0),(G22+K22)/2,MAX(G22,K22)) -> 98726667 | M22: 0.1146 | N22: =IFERROR(INDEX(Assumptions!$D$11:$D$19,MATCH(D22,Assumptions!$A$11:$A$19,0)),0) -> 0.45 | P22: =IFERROR(IF(ISBLANK(O22),N22,O22),0) -> 0.45 | Q22: =IFERROR(Assumptions!$B$5+INDEX(Assumptions!$E$11:$E$19,MATCH(D22,Assumptions!$A$11:$A$19,0)),Assumptions!$B$5) -> 2030 | S22: =IF(ISBLANK(R22),Q22,R22) -> 2030 | T22: =L22*M22 -> 11314076 | U22: =P22*L22*M22 -> 5091334.2 | V22: =P22*G22*M22 -> 5877432.9 | W22: =P22*K22*M22 -> 4305235.5 | X22: =IFERROR(U22/(1+Assumptions!$B$6)^(S22-Assumptions!$B$5),0) -> 2910986.9 | Y22: 2327000 | Z22: =IF(Y22=0,"",U22/Y22) -> 2.1879391 | AA22: =E22*Assumptions!$B$8*M22 -> 9616086 | AB22: Synthetic company. Stage S5.
A23: Company 21 | B23: PC-21 | C23: Health Tech | D23: S3 | E23: 20270000 | F23: =COUNTIFS(Comps!$A$3:$A$700,$A23,Comps!$C$3:$C$700,"Exit",Comps!$G$3:$G$700,"Y") -> 6 | G23: {=IFERROR(MEDIAN(IF((Comps!$A$3:$A$700=$A23)*(Comps!$C$3:$C$700="Exit")*(Comps!$G$3:$G$700="Y"),Comps!$D$3:$D$700)),0)} -> 81215000 | H23: =COUNTIFS(Comps!$A$3:$A$700,$A23,Comps!$C$3:$C$700,"Private",Comps!$G$3:$G$700,"Y") -> 3 | I23: =IFERROR(AVERAGEIFS(Comps!$D$3:$D$700,Comps!$A$3:$A$700,$A23,Comps!$C$3:$C$700,"Private",Comps!$G$3:$G$700,"Y"),0) -> 21856667 | J23: =Assumptions!$B$7 -> 2.5 | K23: =I23*J23 -> 54641667 | L23: =IF(AND(G23>0,K23>0),(G23+K23)/2,MAX(G23,K23)) -> 67928333 | M23: 0.083 | N23: =IFERROR(INDEX(Assumptions!$D$11:$D$19,MATCH(D23,Assumptions!$A$11:$A$19,0)),0) -> 0.2 | P23: =IFERROR(IF(ISBLANK(O23),N23,O23),0) -> 0.2 | Q23: =IFERROR(Assumptions!$B$5+INDEX(Assumptions!$E$11:$E$19,MATCH(D23,Assumptions!$A$11:$A$19,0)),Assumptions!$B$5) -> 2032 | S23: =IF(ISBLANK(R23),Q23,R23) -> 2032 | T23: =L23*M23 -> 5638051.7 | U23: =P23*L23*M23 -> 1127610.3 | V23: =P23*G23*M23 -> 1348169 | W23: =P23*K23*M23 -> 907051.67 | X23: =IFERROR(U23/(1+Assumptions!$B$6)^(S23-Assumptions!$B$5),0) -> 487497.06 | Y23: 708000 | Z23: =IF(Y23=0,"",U23/Y23) -> 1.59267 | AA23: =E23*Assumptions!$B$8*M23 -> 5047230 | AB23: Synthetic company. Stage S3.
A24: Company 22 | B24: PC-22 | C24: Bio tech | D24: S7 | E24: 18850000 | F24: =COUNTIFS(Comps!$A$3:$A$700,$A24,Comps!$C$3:$C$700,"Exit",Comps!$G$3:$G$700,"Y") -> 4 | G24: {=IFERROR(MEDIAN(IF((Comps!$A$3:$A$700=$A24)*(Comps!$C$3:$C$700="Exit")*(Comps!$G$3:$G$700="Y"),Comps!$D$3:$D$700)),0)} -> 27975000 | H24: =COUNTIFS(Comps!$A$3:$A$700,$A24,Comps!$C$3:$C$700,"Private",Comps!$G$3:$G$700,"Y") -> 0 | I24: =IFERROR(AVERAGEIFS(Comps!$D$3:$D$700,Comps!$A$3:$A$700,$A24,Comps!$C$3:$C$700,"Private",Comps!$G$3:$G$700,"Y"),0) -> 0 | J24: =Assumptions!$B$7 -> 2.5 | K24: =I24*J24 -> 0 | L24: =IF(AND(G24>0,K24>0),(G24+K24)/2,MAX(G24,K24)) -> 27975000 | M24: 0.0876 | N24: =IFERROR(INDEX(Assumptions!$D$11:$D$19,MATCH(D24,Assumptions!$A$11:$A$19,0)),0) -> 0.72 | P24: =IFERROR(IF(ISBLANK(O24),N24,O24),0) -> 0.72 | Q24: =IFERROR(Assumptions!$B$5+INDEX(Assumptions!$E$11:$E$19,MATCH(D24,Assumptions!$A$11:$A$19,0)),Assumptions!$B$5) -> 2028 | S24: =IF(ISBLANK(R24),Q24,R24) -> 2028 | T24: =L24*M24 -> 2450610 | U24: =P24*L24*M24 -> 1764439.2 | V24: =P24*G24*M24 -> 1764439.2 | W24: =P24*K24*M24 -> 0 | X24: =IFERROR(U24/(1+Assumptions!$B$6)^(S24-Assumptions!$B$5),0) -> 1334169.5 | Y24: 650000 | Z24: =IF(Y24=0,"",U24/Y24) -> 2.7145218 | AA24: =E24*Assumptions!$B$8*M24 -> 4953780 | AB24: Synthetic company. Stage S7.
A25: Company 23 | B25: PC-23 | C25: Bio tech | D25: S4 | E25: 53550000 | F25: =COUNTIFS(Comps!$A$3:$A$700,$A25,Comps!$C$3:$C$700,"Exit",Comps!$G$3:$G$700,"Y") -> 2 | G25: {=IFERROR(MEDIAN(IF((Comps!$A$3:$A$700=$A25)*(Comps!$C$3:$C$700="Exit")*(Comps!$G$3:$G$700="Y"),Comps!$D$3:$D$700)),0)} -> 239840000 | H25: =COUNTIFS(Comps!$A$3:$A$700,$A25,Comps!$C$3:$C$700,"Private",Comps!$G$3:$G$700,"Y") -> 2 | I25: =IFERROR(AVERAGEIFS(Comps!$D$3:$D$700,Comps!$A$3:$A$700,$A25,Comps!$C$3:$C$700,"Private",Comps!$G$3:$G$700,"Y"),0) -> 83875000 | J25: =Assumptions!$B$7 -> 2.5 | K25: =I25*J25 -> 209687500 | L25: =IF(AND(G25>0,K25>0),(G25+K25)/2,MAX(G25,K25)) -> 224763750 | M25: 0.1322 | N25: =IFERROR(INDEX(Assumptions!$D$11:$D$19,MATCH(D25,Assumptions!$A$11:$A$19,0)),0) -> 0.3 | P25: =IFERROR(IF(ISBLANK(O25),N25,O25),0) -> 0.3 | Q25: =IFERROR(Assumptions!$B$5+INDEX(Assumptions!$E$11:$E$19,MATCH(D25,Assumptions!$A$11:$A$19,0)),Assumptions!$B$5) -> 2031 | S25: =IF(ISBLANK(R25),Q25,R25) -> 2031 | T25: =L25*M25 -> 29713768 | U25: =P25*L25*M25 -> 8914130.3 | V25: =P25*G25*M25 -> 9512054.4 | W25: =P25*K25*M25 -> 8316206.2 | X25: =IFERROR(U25/(1+Assumptions!$B$6)^(S25-Assumptions!$B$5),0) -> 4431898.2 | Y25: 2857000 | Z25: =IF(Y25=0,"",U25/Y25) -> 3.1201016 | AA25: =E25*Assumptions!$B$8*M25 -> 21237930 | AB25: Synthetic company. Stage S4.
A26: Company 24 | B26: PC-24 | C26: Med tech | D26: S4 | E26: 32410000 | F26: =COUNTIFS(Comps!$A$3:$A$700,$A26,Comps!$C$3:$C$700,"Exit",Comps!$G$3:$G$700,"Y") -> 3 | G26: {=IFERROR(MEDIAN(IF((Comps!$A$3:$A$700=$A26)*(Comps!$C$3:$C$700="Exit")*(Comps!$G$3:$G$700="Y"),Comps!$D$3:$D$700)),0)} -> 124750000 | H26: =COUNTIFS(Comps!$A$3:$A$700,$A26,Comps!$C$3:$C$700,"Private",Comps!$G$3:$G$700,"Y") -> 1 | I26: =IFERROR(AVERAGEIFS(Comps!$D$3:$D$700,Comps!$A$3:$A$700,$A26,Comps!$C$3:$C$700,"Private",Comps!$G$3:$G$700,"Y"),0) -> 34610000 | J26: =Assumptions!$B$7 -> 2.5 | K26: =I26*J26 -> 86525000 | L26: =IF(AND(G26>0,K26>0),(G26+K26)/2,MAX(G26,K26)) -> 105637500 | M26: 0.0833 | N26: =IFERROR(INDEX(Assumptions!$D$11:$D$19,MATCH(D26,Assumptions!$A$11:$A$19,0)),0) -> 0.3 | O26: 0.67 | P26: =IFERROR(IF(ISBLANK(O26),N26,O26),0) -> 0.67 | Q26: =IFERROR(Assumptions!$B$5+INDEX(Assumptions!$E$11:$E$19,MATCH(D26,Assumptions!$A$11:$A$19,0)),Assumptions!$B$5) -> 2031 | S26: =IF(ISBLANK(R26),Q26,R26) -> 2031 | T26: =L26*M26 -> 8799603.8 | U26: =P26*L26*M26 -> 5895734.5 | V26: =P26*G26*M26 -> 6962422.2 | W26: =P26*K26*M26 -> 4829046.8 | X26: =IFERROR(U26/(1+Assumptions!$B$6)^(S26-Assumptions!$B$5),0) -> 2931222 | Y26: 2212000 | Z26: =IF(Y26=0,"",U26/Y26) -> 2.6653411 | AA26: =E26*Assumptions!$B$8*M26 -> 8099259 | AB26: Synthetic company. Stage S4. P(exit) overridden to 67% (exit-predictor style input).
A27: Company 25 | B27: PC-25 | C27: Med tech | D27: S4 | E27: 84430000 | F27: =COUNTIFS(Comps!$A$3:$A$700,$A27,Comps!$C$3:$C$700,"Exit",Comps!$G$3:$G$700,"Y") -> 2 | G27: {=IFERROR(MEDIAN(IF((Comps!$A$3:$A$700=$A27)*(Comps!$C$3:$C$700="Exit")*(Comps!$G$3:$G$700="Y"),Comps!$D$3:$D$700)),0)} -> 495115000 | H27: =COUNTIFS(Comps!$A$3:$A$700,$A27,Comps!$C$3:$C$700,"Private",Comps!$G$3:$G$700,"Y") -> 3 | I27: =IFERROR(AVERAGEIFS(Comps!$D$3:$D$700,Comps!$A$3:$A$700,$A27,Comps!$C$3:$C$700,"Private",Comps!$G$3:$G$700,"Y"),0) -> 87820000 | J27: =Assumptions!$B$7 -> 2.5 | K27: =I27*J27 -> 219550000 | L27: =IF(AND(G27>0,K27>0),(G27+K27)/2,MAX(G27,K27)) -> 357332500 | M27: 0.131 | N27: =IFERROR(INDEX(Assumptions!$D$11:$D$19,MATCH(D27,Assumptions!$A$11:$A$19,0)),0) -> 0.3 | P27: =IFERROR(IF(ISBLANK(O27),N27,O27),0) -> 0.3 | Q27: =IFERROR(Assumptions!$B$5+INDEX(Assumptions!$E$11:$E$19,MATCH(D27,Assumptions!$A$11:$A$19,0)),Assumptions!$B$5) -> 2031 | S27: =IF(ISBLANK(R27),Q27,R27) -> 2031 | T27: =L27*M27 -> 46810558 | U27: =P27*L27*M27 -> 14043167 | V27: =P27*G27*M27 -> 19458020 | W27: =P27*K27*M27 -> 8628315 | X27: =IFERROR(U27/(1+Assumptions!$B$6)^(S27-Assumptions!$B$5),0) -> 6981936 | Y27: 5208000 | Z27: =IF(Y27=0,"",U27/Y27) -> 2.6964607 | AA27: =E27*Assumptions!$B$8*M27 -> 33180990 | AB27: Synthetic company. Stage S4.
A28: Company 26 | B28: PC-26 | C28: Med tech | D28: S4 | E28: 58020000 | F28: =COUNTIFS(Comps!$A$3:$A$700,$A28,Comps!$C$3:$C$700,"Exit",Comps!$G$3:$G$700,"Y") -> 4 | G28: {=IFERROR(MEDIAN(IF((Comps!$A$3:$A$700=$A28)*(Comps!$C$3:$C$700="Exit")*(Comps!$G$3:$G$700="Y"),Comps!$D$3:$D$700)),0)} -> 225745000 | H28: =COUNTIFS(Comps!$A$3:$A$700,$A28,Comps!$C$3:$C$700,"Private",Comps!$G$3:$G$700,"Y") -> 3 | I28: =IFERROR(AVERAGEIFS(Comps!$D$3:$D$700,Comps!$A$3:$A$700,$A28,Comps!$C$3:$C$700,"Private",Comps!$G$3:$G$700,"Y"),0) -> 94810000 | J28: =Assumptions!$B$7 -> 2.5 | K28: =I28*J28 -> 237025000 | L28: =IF(AND(G28>0,K28>0),(G28+K28)/2,MAX(G28,K28)) -> 231385000 | M28: 0.0864 | N28: =IFERROR(INDEX(Assumptions!$D$11:$D$19,MATCH(D28,Assumptions!$A$11:$A$19,0)),0) -> 0.3 | O28: 0.69 | P28: =IFERROR(IF(ISBLANK(O28),N28,O28),0) -> 0.69 | Q28: =IFERROR(Assumptions!$B$5+INDEX(Assumptions!$E$11:$E$19,MATCH(D28,Assumptions!$A$11:$A$19,0)),Assumptions!$B$5) -> 2031 | R28: 2034 | S28: =IF(ISBLANK(R28),Q28,R28) -> 2034 | T28: =L28*M28 -> 19991664 | U28: =P28*L28*M28 -> 13794248 | V28: =P28*G28*M28 -> 13458014 | W28: =P28*K28*M28 -> 14130482 | X28: =IFERROR(U28/(1+Assumptions!$B$6)^(S28-Assumptions!$B$5),0) -> 4509364.2 | Y28: 4200000 | Z28: =IF(Y28=0,"",U28/Y28) -> 3.2843448 | AA28: =E28*Assumptions!$B$8*M28 -> 15038784 | AB28: Synthetic company. Stage S4. P(exit) overridden to 69% (exit-predictor style input). Exit year overridden to 2034 (long regulatory path).
A29: Company 27 | B29: PC-27 | C29: Med tech | D29: S4 | E29: 43730000 | F29: =COUNTIFS(Comps!$A$3:$A$700,$A29,Comps!$C$3:$C$700,"Exit",Comps!$G$3:$G$700,"Y") -> 3 | G29: {=IFERROR(MEDIAN(IF((Comps!$A$3:$A$700=$A29)*(Comps!$C$3:$C$700="Exit")*(Comps!$G$3:$G$700="Y"),Comps!$D$3:$D$700)),0)} -> 144020000 | H29: =COUNTIFS(Comps!$A$3:$A$700,$A29,Comps!$C$3:$C$700,"Private",Comps!$G$3:$G$700,"Y") -> 2 | I29: =IFERROR(AVERAGEIFS(Comps!$D$3:$D$700,Comps!$A$3:$A$700,$A29,Comps!$C$3:$C$700,"Private",Comps!$G$3:$G$700,"Y"),0) -> 97195000 | J29: =Assumptions!$B$7 -> 2.5 | K29: =I29*J29 -> 242987500 | L29: =IF(AND(G29>0,K29>0),(G29+K29)/2,MAX(G29,K29)) -> 193503750 | M29: 0.0309 | N29: =IFERROR(INDEX(Assumptions!$D$11:$D$19,MATCH(D29,Assumptions!$A$11:$A$19,0)),0) -> 0.3 | P29: =IFERROR(IF(ISBLANK(O29),N29,O29),0) -> 0.3 | Q29: =IFERROR(Assumptions!$B$5+INDEX(Assumptions!$E$11:$E$19,MATCH(D29,Assumptions!$A$11:$A$19,0)),Assumptions!$B$5) -> 2031 | S29: =IF(ISBLANK(R29),Q29,R29) -> 2031 | T29: =L29*M29 -> 5979265.9 | U29: =P29*L29*M29 -> 1793779.8 | V29: =P29*G29*M29 -> 1335065.4 | W29: =P29*K29*M29 -> 2252494.1 | X29: =IFERROR(U29/(1+Assumptions!$B$6)^(S29-Assumptions!$B$5),0) -> 891825.57 | Y29: 902000 | Z29: =IF(Y29=0,"",U29/Y29) -> 1.9886694 | AA29: =E29*Assumptions!$B$8*M29 -> 4053771 | AB29: Synthetic company. Stage S4.
A30: Company 28 | B30: PC-28 | C30: Bio tech | D30: S7 | E30: 21340000 | F30: =COUNTIFS(Comps!$A$3:$A$700,$A30,Comps!$C$3:$C$700,"Exit",Comps!$G$3:$G$700,"Y") -> 2 | G30: {=IFERROR(MEDIAN(IF((Comps!$A$3:$A$700=$A30)*(Comps!$C$3:$C$700="Exit")*(Comps!$G$3:$G$700="Y"),Comps!$D$3:$D$700)),0)} -> 53545000 | H30: =COUNTIFS(Comps!$A$3:$A$700,$A30,Comps!$C$3:$C$700,"Private",Comps!$G$3:$G$700,"Y") -> 4 | I30: =IFERROR(AVERAGEIFS(Comps!$D$3:$D$700,Comps!$A$3:$A$700,$A30,Comps!$C$3:$C$700,"Private",Comps!$G$3:$G$700,"Y"),0) -> 32620000 | J30: =Assumptions!$B$7 -> 2.5 | K30: =I30*J30 -> 81550000 | L30: =IF(AND(G30>0,K30>0),(G30+K30)/2,MAX(G30,K30)) -> 67547500 | M30: 0.0371 | N30: =IFERROR(INDEX(Assumptions!$D$11:$D$19,MATCH(D30,Assumptions!$A$11:$A$19,0)),0) -> 0.72 | P30: =IFERROR(IF(ISBLANK(O30),N30,O30),0) -> 0.72 | Q30: =IFERROR(Assumptions!$B$5+INDEX(Assumptions!$E$11:$E$19,MATCH(D30,Assumptions!$A$11:$A$19,0)),Assumptions!$B$5) -> 2028 | S30: =IF(ISBLANK(R30),Q30,R30) -> 2028 | T30: =L30*M30 -> 2506012.2 | U30: =P30*L30*M30 -> 1804328.8 | V30: =P30*G30*M30 -> 1430294 | W30: =P30*K30*M30 -> 2178363.6 | X30: =IFERROR(U30/(1+Assumptions!$B$6)^(S30-Assumptions!$B$5),0) -> 1364331.8 | Y30: 443000 | Z30: =IF(Y30=0,"",U30/Y30) -> 4.072977 | AA30: =E30*Assumptions!$B$8*M30 -> 2375142 | AB30: Synthetic company. Stage S7.
A31: Company 29 | B31: PC-29 | C31: Med tech | D31: S4 | E31: 37900000 | F31: =COUNTIFS(Comps!$A$3:$A$700,$A31,Comps!$C$3:$C$700,"Exit",Comps!$G$3:$G$700,"Y") -> 6 | G31: {=IFERROR(MEDIAN(IF((Comps!$A$3:$A$700=$A31)*(Comps!$C$3:$C$700="Exit")*(Comps!$G$3:$G$700="Y"),Comps!$D$3:$D$700)),0)} -> 115540000 | H31: =COUNTIFS(Comps!$A$3:$A$700,$A31,Comps!$C$3:$C$700,"Private",Comps!$G$3:$G$700,"Y") -> 3 | I31: =IFERROR(AVERAGEIFS(Comps!$D$3:$D$700,Comps!$A$3:$A$700,$A31,Comps!$C$3:$C$700,"Private",Comps!$G$3:$G$700,"Y"),0) -> 82240000 | J31: =Assumptions!$B$7 -> 2.5 | K31: =I31*J31 -> 205600000 | L31: =IF(AND(G31>0,K31>0),(G31+K31)/2,MAX(G31,K31)) -> 160570000 | M31: 0.1625 | N31: =IFERROR(INDEX(Assumptions!$D$11:$D$19,MATCH(D31,Assumptions!$A$11:$A$19,0)),0) -> 0.3 | O31: 0.38 | P31: =IFERROR(IF(ISBLANK(O31),N31,O31),0) -> 0.38 | Q31: =IFERROR(Assumptions!$B$5+INDEX(Assumptions!$E$11:$E$19,MATCH(D31,Assumptions!$A$11:$A$19,0)),Assumptions!$B$5) -> 2031 | S31: =IF(ISBLANK(R31),Q31,R31) -> 2031 | T31: =L31*M31 -> 26092625 | U31: =P31*L31*M31 -> 9915197.5 | V31: =P31*G31*M31 -> 7134595 | W31: =P31*K31*M31 -> 12695800 | X31: =IFERROR(U31/(1+Assumptions!$B$6)^(S31-Assumptions!$B$5),0) -> 4929605.5 | Y31: 4464000 | Z31: =IF(Y31=0,"",U31/Y31) -> 2.2211464 | AA31: =E31*Assumptions!$B$8*M31 -> 18476250 | AB31: Synthetic company. Stage S4. P(exit) overridden to 38% (exit-predictor style input).
A32: Company 30 | B32: PC-30 | C32: Bio tech | D32: S7 | E32: 13430000 | F32: =COUNTIFS(Comps!$A$3:$A$700,$A32,Comps!$C$3:$C$700,"Exit",Comps!$G$3:$G$700,"Y") -> 3 | G32: {=IFERROR(MEDIAN(IF((Comps!$A$3:$A$700=$A32)*(Comps!$C$3:$C$700="Exit")*(Comps!$G$3:$G$700="Y"),Comps!$D$3:$D$700)),0)} -> 18920000 | H32: =COUNTIFS(Comps!$A$3:$A$700,$A32,Comps!$C$3:$C$700,"Private",Comps!$G$3:$G$700,"Y") -> 1 | I32: =IFERROR(AVERAGEIFS(Comps!$D$3:$D$700,Comps!$A$3:$A$700,$A32,Comps!$C$3:$C$700,"Private",Comps!$G$3:$G$700,"Y"),0) -> 9740000 | J32: =Assumptions!$B$7 -> 2.5 | K32: =I32*J32 -> 24350000 | L32: =IF(AND(G32>0,K32>0),(G32+K32)/2,MAX(G32,K32)) -> 21635000 | M32: 0.0711 | N32: =IFERROR(INDEX(Assumptions!$D$11:$D$19,MATCH(D32,Assumptions!$A$11:$A$19,0)),0) -> 0.72 | P32: =IFERROR(IF(ISBLANK(O32),N32,O32),0) -> 0.72 | Q32: =IFERROR(Assumptions!$B$5+INDEX(Assumptions!$E$11:$E$19,MATCH(D32,Assumptions!$A$11:$A$19,0)),Assumptions!$B$5) -> 2028 | S32: =IF(ISBLANK(R32),Q32,R32) -> 2028 | T32: =L32*M32 -> 1538248.5 | U32: =P32*L32*M32 -> 1107538.9 | V32: =P32*G32*M32 -> 968552.64 | W32: =P32*K32*M32 -> 1246525.2 | X32: =IFERROR(U32/(1+Assumptions!$B$6)^(S32-Assumptions!$B$5),0) -> 837458.54 | Y32: 417000 | Z32: =IF(Y32=0,"",U32/Y32) -> 2.6559686 | AA32: =E32*Assumptions!$B$8*M32 -> 2864619 | AB32: Synthetic company. Stage S7.
A33: Company 31 | B33: PC-31 | C33: Bio tech | D33: S6 | E33: 82520000 | F33: =COUNTIFS(Comps!$A$3:$A$700,$A33,Comps!$C$3:$C$700,"Exit",Comps!$G$3:$G$700,"Y") -> 4 | G33: {=IFERROR(MEDIAN(IF((Comps!$A$3:$A$700=$A33)*(Comps!$C$3:$C$700="Exit")*(Comps!$G$3:$G$700="Y"),Comps!$D$3:$D$700)),0)} -> 408960000 | H33: =COUNTIFS(Comps!$A$3:$A$700,$A33,Comps!$C$3:$C$700,"Private",Comps!$G$3:$G$700,"Y") -> 5 | I33: =IFERROR(AVERAGEIFS(Comps!$D$3:$D$700,Comps!$A$3:$A$700,$A33,Comps!$C$3:$C$700,"Private",Comps!$G$3:$G$700,"Y"),0) -> 104762000 | J33: =Assumptions!$B$7 -> 2.5 | K33: =I33*J33 -> 261905000 | L33: =IF(AND(G33>0,K33>0),(G33+K33)/2,MAX(G33,K33)) -> 335432500 | M33: 0.1037 | N33: =IFERROR(INDEX(Assumptions!$D$11:$D$19,MATCH(D33,Assumptions!$A$11:$A$19,0)),0) -> 0.62 | P33: =IFERROR(IF(ISBLANK(O33),N33,O33),0) -> 0.62 | Q33: =IFERROR(Assumptions!$B$5+INDEX(Assumptions!$E$11:$E$19,MATCH(D33,Assumptions!$A$11:$A$19,0)),Assumptions!$B$5) -> 2029 | S33: =IF(ISBLANK(R33),Q33,R33) -> 2029 | T33: =L33*M33 -> 34784350 | U33: =P33*L33*M33 -> 21566297 | V33: =P33*G33*M33 -> 26293674 | W33: =P33*K33*M33 -> 16838920 | X33: =IFERROR(U33/(1+Assumptions!$B$6)^(S33-Assumptions!$B$5),0) -> 14180190 | Y33: 6749000 | Z33: =IF(Y33=0,"",U33/Y33) -> 3.1954804 | AA33: =E33*Assumptions!$B$8*M33 -> 25671972 | AB33: Synthetic company. Stage S6.
A34: Company 32 | B34: PC-32 | C34: Bio tech | D34: S7 | E34: 37020000 | F34: =COUNTIFS(Comps!$A$3:$A$700,$A34,Comps!$C$3:$C$700,"Exit",Comps!$G$3:$G$700,"Y") -> 3 | G34: {=IFERROR(MEDIAN(IF((Comps!$A$3:$A$700=$A34)*(Comps!$C$3:$C$700="Exit")*(Comps!$G$3:$G$700="Y"),Comps!$D$3:$D$700)),0)} -> 55810000 | H34: =COUNTIFS(Comps!$A$3:$A$700,$A34,Comps!$C$3:$C$700,"Private",Comps!$G$3:$G$700,"Y") -> 3 | I34: =IFERROR(AVERAGEIFS(Comps!$D$3:$D$700,Comps!$A$3:$A$700,$A34,Comps!$C$3:$C$700,"Private",Comps!$G$3:$G$700,"Y"),0) -> 32596667 | J34: 1 | K34: =I34*J34 -> 32596667 | L34: =IF(AND(G34>0,K34>0),(G34+K34)/2,MAX(G34,K34)) -> 44203333 | M34: 0.0321 | N34: =IFERROR(INDEX(Assumptions!$D$11:$D$19,MATCH(D34,Assumptions!$A$11:$A$19,0)),0) -> 0.72 | P34: =IFERROR(IF(ISBLANK(O34),N34,O34),0) -> 0.72 | Q34: =IFERROR(Assumptions!$B$5+INDEX(Assumptions!$E$11:$E$19,MATCH(D34,Assumptions!$A$11:$A$19,0)),Assumptions!$B$5) -> 2028 | S34: =IF(ISBLANK(R34),Q34,R34) -> 2028 | T34: =L34*M34 -> 1418927 | U34: =P34*L34*M34 -> 1021627.4 | V34: =P34*G34*M34 -> 1289880.7 | W34: =P34*K34*M34 -> 753374.16 | X34: =IFERROR(U34/(1+Assumptions!$B$6)^(S34-Assumptions!$B$5),0) -> 772497.12 | Y34: 1063000 | Z34: =IF(Y34=0,"",U34/Y34) -> 0.96107944 | AA34: =E34*Assumptions!$B$8*M34 -> 3565026 | AB34: Synthetic company. Stage S7. Private step-up set to 1.0x: peers already at exit-scale valuations.
A35: Company 33 | B35: PC-33 | C35: Bio tech | D35: X | E35: 900000000 | F35: =COUNTIFS(Comps!$A$3:$A$700,$A35,Comps!$C$3:$C$700,"Exit",Comps!$G$3:$G$700,"Y") -> 1 | G35: {=IFERROR(MEDIAN(IF((Comps!$A$3:$A$700=$A35)*(Comps!$C$3:$C$700="Exit")*(Comps!$G$3:$G$700="Y"),Comps!$D$3:$D$700)),0)} -> 900000000 | H35: =COUNTIFS(Comps!$A$3:$A$700,$A35,Comps!$C$3:$C$700,"Private",Comps!$G$3:$G$700,"Y") -> 0 | I35: =IFERROR(AVERAGEIFS(Comps!$D$3:$D$700,Comps!$A$3:$A$700,$A35,Comps!$C$3:$C$700,"Private",Comps!$G$3:$G$700,"Y"),0) -> 0 | J35: =Assumptions!$B$7 -> 2.5 | K35: =I35*J35 -> 0 | L35: =IF(AND(G35>0,K35>0),(G35+K35)/2,MAX(G35,K35)) -> 900000000 | M35: 0.035 | N35: =IFERROR(INDEX(Assumptions!$D$11:$D$19,MATCH(D35,Assumptions!$A$11:$A$19,0)),0) -> 1 | P35: =IFERROR(IF(ISBLANK(O35),N35,O35),0) -> 1 | Q35: =IFERROR(Assumptions!$B$5+INDEX(Assumptions!$E$11:$E$19,MATCH(D35,Assumptions!$A$11:$A$19,0)),Assumptions!$B$5) -> 2026 | S35: =IF(ISBLANK(R35),Q35,R35) -> 2026 | T35: =L35*M35 -> 31500000 | U35: =P35*L35*M35 -> 31500000 | V35: =P35*G35*M35 -> 31500000 | W35: =P35*K35*M35 -> 0 | X35: =IFERROR(U35/(1+Assumptions!$B$6)^(S35-Assumptions!$B$5),0) -> 31500000 | Y35: 7553000 | Z35: =IF(Y35=0,"",U35/Y35) -> 4.1705283 | AA35: =E35*Assumptions!$B$8*M35 -> 94500000 | AB35: Synthetic company. Stage X. Realized exit: value is the actual deal, P(exit) = 100%.
A36: Company 34 | B36: PC-34 | C36: Med tech | D36: S2 | E36: 21170000 | F36: =COUNTIFS(Comps!$A$3:$A$700,$A36,Comps!$C$3:$C$700,"Exit",Comps!$G$3:$G$700,"Y") -> 6 | G36: {=IFERROR(MEDIAN(IF((Comps!$A$3:$A$700=$A36)*(Comps!$C$3:$C$700="Exit")*(Comps!$G$3:$G$700="Y"),Comps!$D$3:$D$700)),0)} -> 108115000 | H36: =COUNTIFS(Comps!$A$3:$A$700,$A36,Comps!$C$3:$C$700,"Private",Comps!$G$3:$G$700,"Y") -> 2 | I36: =IFERROR(AVERAGEIFS(Comps!$D$3:$D$700,Comps!$A$3:$A$700,$A36,Comps!$C$3:$C$700,"Private",Comps!$G$3:$G$700,"Y"),0) -> 28280000 | J36: =Assumptions!$B$7 -> 2.5 | K36: =I36*J36 -> 70700000 | L36: =IF(AND(G36>0,K36>0),(G36+K36)/2,MAX(G36,K36)) -> 89407500 | M36: 0.1196 | N36: =IFERROR(INDEX(Assumptions!$D$11:$D$19,MATCH(D36,Assumptions!$A$11:$A$19,0)),0) -> 0.13 | O36: 0.76 | P36: =IFERROR(IF(ISBLANK(O36),N36,O36),0) -> 0.76 | Q36: =IFERROR(Assumptions!$B$5+INDEX(Assumptions!$E$11:$E$19,MATCH(D36,Assumptions!$A$11:$A$19,0)),Assumptions!$B$5) -> 2033 | S36: =IF(ISBLANK(R36),Q36,R36) -> 2033 | T36: =L36*M36 -> 10693137 | U36: =P36*L36*M36 -> 8126784.1 | V36: =P36*G36*M36 -> 9827221 | W36: =P36*K36*M36 -> 6426347.2 | X36: =IFERROR(U36/(1+Assumptions!$B$6)^(S36-Assumptions!$B$5),0) -> 3055159.2 | Y36: 2051000 | Z36: =IF(Y36=0,"",U36/Y36) -> 3.9623521 | AA36: =E36*Assumptions!$B$8*M36 -> 7595796 | AB36: Synthetic company. Stage S2. P(exit) overridden to 76% (exit-predictor style input).
A37: Company 35 | B37: PC-35 | C37: Health Tech | D37: S2 | E37: 20760000 | F37: =COUNTIFS(Comps!$A$3:$A$700,$A37,Comps!$C$3:$C$700,"Exit",Comps!$G$3:$G$700,"Y") -> 2 | G37: {=IFERROR(MEDIAN(IF((Comps!$A$3:$A$700=$A37)*(Comps!$C$3:$C$700="Exit")*(Comps!$G$3:$G$700="Y"),Comps!$D$3:$D$700)),0)} -> 62545000 | H37: =COUNTIFS(Comps!$A$3:$A$700,$A37,Comps!$C$3:$C$700,"Private",Comps!$G$3:$G$700,"Y") -> 1 | I37: =IFERROR(AVERAGEIFS(Comps!$D$3:$D$700,Comps!$A$3:$A$700,$A37,Comps!$C$3:$C$700,"Private",Comps!$G$3:$G$700,"Y"),0) -> 28950000 | J37: =Assumptions!$B$7 -> 2.5 | K37: =I37*J37 -> 72375000 | L37: =IF(AND(G37>0,K37>0),(G37+K37)/2,MAX(G37,K37)) -> 67460000 | M37: 0.0191 | N37: =IFERROR(INDEX(Assumptions!$D$11:$D$19,MATCH(D37,Assumptions!$A$11:$A$19,0)),0) -> 0.13 | P37: =IFERROR(IF(ISBLANK(O37),N37,O37),0) -> 0.13 | Q37: =IFERROR(Assumptions!$B$5+INDEX(Assumptions!$E$11:$E$19,MATCH(D37,Assumptions!$A$11:$A$19,0)),Assumptions!$B$5) -> 2033 | S37: =IF(ISBLANK(R37),Q37,R37) -> 2033 | T37: =L37*M37 -> 1288486 | U37: =P37*L37*M37 -> 167503.18 | V37: =P37*G37*M37 -> 155299.23 | W37: =P37*K37*M37 -> 179707.12 | X37: =IFERROR(U37/(1+Assumptions!$B$6)^(S37-Assumptions!$B$5),0) -> 62970.65 | Y37: 168000 | Z37: =IF(Y37=0,"",U37/Y37) -> 0.99704274 | AA37: =E37*Assumptions!$B$8*M37 -> 1189548 | AB37: Synthetic company. Stage S2.
A38: Company 36 | B38: PC-36 | C38: Med tech | D38: S7 | E38: 37020000 | F38: =COUNTIFS(Comps!$A$3:$A$700,$A38,Comps!$C$3:$C$700,"Exit",Comps!$G$3:$G$700,"Y") -> 6 | G38: {=IFERROR(MEDIAN(IF((Comps!$A$3:$A$700=$A38)*(Comps!$C$3:$C$700="Exit")*(Comps!$G$3:$G$700="Y"),Comps!$D$3:$D$700)),0)} -> 75165000 | H38: =COUNTIFS(Comps!$A$3:$A$700,$A38,Comps!$C$3:$C$700,"Private",Comps!$G$3:$G$700,"Y") -> 1 | I38: =IFERROR(AVERAGEIFS(Comps!$D$3:$D$700,Comps!$A$3:$A$700,$A38,Comps!$C$3:$C$700,"Private",Comps!$G$3:$G$700,"Y"),0) -> 20940000 | J38: =Assumptions!$B$7 -> 2.5 | K38: =I38*J38 -> 52350000 | L38: =IF(AND(G38>0,K38>0),(G38+K38)/2,MAX(G38,K38)) -> 63757500 | M38: 0.0255 | N38: =IFERROR(INDEX(Assumptions!$D$11:$D$19,MATCH(D38,Assumptions!$A$11:$A$19,0)),0) -> 0.72 | P38: =IFERROR(IF(ISBLANK(O38),N38,O38),0) -> 0.72 | Q38: =IFERROR(Assumptions!$B$5+INDEX(Assumptions!$E$11:$E$19,MATCH(D38,Assumptions!$A$11:$A$19,0)),Assumptions!$B$5) -> 2028 | S38: =IF(ISBLANK(R38),Q38,R38) -> 2028 | T38: =L38*M38 -> 1625816.2 | U38: =P38*L38*M38 -> 1170587.7 | V38: =P38*G38*M38 -> 1380029.4 | W38: =P38*K38*M38 -> 961146 | X38: =IFERROR(U38/(1+Assumptions!$B$6)^(S38-Assumptions!$B$5),0) -> 885132.48 | Y38: 693000 | Z38: =IF(Y38=0,"",U38/Y38) -> 1.6891597 | AA38: =E38*Assumptions!$B$8*M38 -> 2832030 | AB38: Synthetic company. Stage S7.
A39: Company 37 | B39: PC-37 | C39: Bio tech | D39: S7 | E39: 35690000 | F39: =COUNTIFS(Comps!$A$3:$A$700,$A39,Comps!$C$3:$C$700,"Exit",Comps!$G$3:$G$700,"Y") -> 2 | G39: {=IFERROR(MEDIAN(IF((Comps!$A$3:$A$700=$A39)*(Comps!$C$3:$C$700="Exit")*(Comps!$G$3:$G$700="Y"),Comps!$D$3:$D$700)),0)} -> 63315000 | H39: =COUNTIFS(Comps!$A$3:$A$700,$A39,Comps!$C$3:$C$700,"Private",Comps!$G$3:$G$700,"Y") -> 2 | I39: =IFERROR(AVERAGEIFS(Comps!$D$3:$D$700,Comps!$A$3:$A$700,$A39,Comps!$C$3:$C$700,"Private",Comps!$G$3:$G$700,"Y"),0) -> 31800000 | J39: =Assumptions!$B$7 -> 2.5 | K39: =I39*J39 -> 79500000 | L39: =IF(AND(G39>0,K39>0),(G39+K39)/2,MAX(G39,K39)) -> 71407500 | M39: 0.0365 | N39: =IFERROR(INDEX(Assumptions!$D$11:$D$19,MATCH(D39,Assumptions!$A$11:$A$19,0)),0) -> 0.72 | P39: =IFERROR(IF(ISBLANK(O39),N39,O39),0) -> 0.72 | Q39: =IFERROR(Assumptions!$B$5+INDEX(Assumptions!$E$11:$E$19,MATCH(D39,Assumptions!$A$11:$A$19,0)),Assumptions!$B$5) -> 2028 | S39: =IF(ISBLANK(R39),Q39,R39) -> 2028 | T39: =L39*M39 -> 2606373.8 | U39: =P39*L39*M39 -> 1876589.1 | V39: =P39*G39*M39 -> 1663918.2 | W39: =P39*K39*M39 -> 2089260 | X39: =IFERROR(U39/(1+Assumptions!$B$6)^(S39-Assumptions!$B$5),0) -> 1418971 | Y39: 745000 | Z39: =IF(Y39=0,"",U39/Y39) -> 2.5189115 | AA39: =E39*Assumptions!$B$8*M39 -> 3908055 | AB39: Synthetic company. Stage S7.
A40: Company 38 | B40: PC-38 | C40: Med tech | D40: S7 | E40: 20330000 | F40: =COUNTIFS(Comps!$A$3:$A$700,$A40,Comps!$C$3:$C$700,"Exit",Comps!$G$3:$G$700,"Y") -> 4 | G40: {=IFERROR(MEDIAN(IF((Comps!$A$3:$A$700=$A40)*(Comps!$C$3:$C$700="Exit")*(Comps!$G$3:$G$700="Y"),Comps!$D$3:$D$700)),0)} -> 43950000 | H40: =COUNTIFS(Comps!$A$3:$A$700,$A40,Comps!$C$3:$C$700,"Private",Comps!$G$3:$G$700,"Y") -> 3 | I40: =IFERROR(AVERAGEIFS(Comps!$D$3:$D$700,Comps!$A$3:$A$700,$A40,Comps!$C$3:$C$700,"Private",Comps!$G$3:$G$700,"Y"),0) -> 35160000 | J40: =Assumptions!$B$7 -> 2.5 | K40: =I40*J40 -> 87900000 | L40: =IF(AND(G40>0,K40>0),(G40+K40)/2,MAX(G40,K40)) -> 65925000 | M40: 0.0685 | N40: =IFERROR(INDEX(Assumptions!$D$11:$D$19,MATCH(D40,Assumptions!$A$11:$A$19,0)),0) -> 0.72 | O40: 0.37 | P40: =IFERROR(IF(ISBLANK(O40),N40,O40),0) -> 0.37 | Q40: =IFERROR(Assumptions!$B$5+INDEX(Assumptions!$E$11:$E$19,MATCH(D40,Assumptions!$A$11:$A$19,0)),Assumptions!$B$5) -> 2028 | S40: =IF(ISBLANK(R40),Q40,R40) -> 2028 | T40: =L40*M40 -> 4515862.5 | U40: =P40*L40*M40 -> 1670869.1 | V40: =P40*G40*M40 -> 1113912.8 | W40: =P40*K40*M40 -> 2227825.5 | X40: =IFERROR(U40/(1+Assumptions!$B$6)^(S40-Assumptions!$B$5),0) -> 1263417.1 | Y40: 1058000 | Z40: =IF(Y40=0,"",U40/Y40) -> 1.5792714 | AA40: =E40*Assumptions!$B$8*M40 -> 4177815 | AB40: Synthetic company. Stage S7. P(exit) overridden to 37% (exit-predictor style input).
...

Sheet Valuation Model 2
A1: Valuation Model 2 (adds follow-on reserves)
A2: Company | B2: Code | C2: Sector | D2: Stage | E2: Current Val internal ($) | F2: # Exit comps | G2: Exit Value Exit comps ($) (Median) | H2: # Private comps | I2: Private peer val mean ($) | J2: Step-up to exit (x) | K2: Exit Value Private comps ($) | L2: Exit Value Average ($) | M2: Fund FD Ownership (%) | N2: P: default | O2: P: override | P2: P: used | Q2: Exit Yr: default | R2: Exit Yr: override | S2: Exit Yr: used | T2: Gross exit to fund ($) | U2: Risk-Adj Average ($) | V2: Risk-Adj — Exit basis ($) | W2: Risk-Adj — Private basis ($) | X2: PV of Risk-Adj ($) | Y2: Total Invested ($) | Z2: Exp. MOIC | AA2: Legacy method exit ($) | AB2: Notes | AC2: Reserve ratio (stage) | AD2: Follow-on to hold pro-rata ($) | AE2: Total capital deployed ($) | AF2: Net Exp. MOIC (incl. reserves)
A3: Company 01 | B3: PC-01 | C3: Bio tech | D3: S2 | E3: 15790000 | F3: =COUNTIFS(Comps!$A$3:$A$700,$A3,Comps!$C$3:$C$700,"Exit",Comps!$G$3:$G$700,"Y") -> 1 | G3: {=IFERROR(MEDIAN(IF((Comps!$A$3:$A$700=$A3)*(Comps!$C$3:$C$700="Exit")*(Comps!$G$3:$G$700="Y"),Comps!$D$3:$D$700)),0)} -> 38930000 | H3: =COUNTIFS(Comps!$A$3:$A$700,$A3,Comps!$C$3:$C$700,"Private",Comps!$G$3:$G$700,"Y") -> 4 | I3: =IFERROR(AVERAGEIFS(Comps!$D$3:$D$700,Comps!$A$3:$A$700,$A3,Comps!$C$3:$C$700,"Private",Comps!$G$3:$G$700,"Y"),0) -> 22752500 | J3: =Assumptions!$B$7 -> 2.5 | K3: =I3*J3 -> 56881250 | L3: =IF(AND(G3>0,K3>0),(G3+K3)/2,MAX(G3,K3)) -> 47905625 | M3: 0.0732 | N3: =IFERROR(INDEX(Assumptions!$D$11:$D$19,MATCH(D3,Assumptions!$A$11:$A$19,0)),0) -> 0.13 | P3: =IFERROR(IF(ISBLANK(O3),N3,O3),0) -> 0.13 | Q3: =IFERROR(Assumptions!$B$5+INDEX(Assumptions!$E$11:$E$19,MATCH(D3,Assumptions!$A$11:$A$19,0)),Assumptions!$B$5) -> 2033 | S3: =IF(ISBLANK(R3),Q3,R3) -> 2033 | T3: =L3*M3 -> 3506691.8 | U3: =P3*L3*M3 -> 455869.93 | V3: =P3*G3*M3 -> 370457.88 | W3: =P3*K3*M3 -> 541281.97 | X3: =IFERROR(U3/(1+Assumptions!$B$6)^(S3-Assumptions!$B$5),0) -> 171378.39 | Y3: 612000 | Z3: =IF(Y3=0,"",U3/Y3) -> 0.7448855 | AA3: =E3*Assumptions!$B$8*M3 -> 3467484 | AB3: Synthetic company. Stage S2. | AC3: =IFERROR(INDEX(Assumptions!$F$11:$F$19,MATCH(D3,Assumptions!$A$11:$A$19,0)),0) -> 2 | AD3: =Y3*AC3 -> 1224000 | AE3: =Y3+AD3 -> 1836000 | AF3: =IF(AE3=0,"",U3/AE3) -> 0.24829517
A4: Company 02 | B4: PC-02 | C4: Bio tech | D4: D | E4: 0 | F4: =COUNTIFS(Comps!$A$3:$A$700,$A4,Comps!$C$3:$C$700,"Exit",Comps!$G$3:$G$700,"Y") -> 0 | G4: {=IFERROR(MEDIAN(IF((Comps!$A$3:$A$700=$A4)*(Comps!$C$3:$C$700="Exit")*(Comps!$G$3:$G$700="Y"),Comps!$D$3:$D$700)),0)} -> 0 | H4: =COUNTIFS(Comps!$A$3:$A$700,$A4,Comps!$C$3:$C$700,"Private",Comps!$G$3:$G$700,"Y") -> 0 | I4: =IFERROR(AVERAGEIFS(Comps!$D$3:$D$700,Comps!$A$3:$A$700,$A4,Comps!$C$3:$C$700,"Private",Comps!$G$3:$G$700,"Y"),0) -> 0 | J4: =Assumptions!$B$7 -> 2.5 | K4: =I4*J4 -> 0 | L4: =IF(AND(G4>0,K4>0),(G4+K4)/2,MAX(G4,K4)) -> 0 | M4: 0.0426 | N4: =IFERROR(INDEX(Assumptions!$D$11:$D$19,MATCH(D4,Assumptions!$A$11:$A$19,0)),0) -> 0.03 | P4: =IFERROR(IF(ISBLANK(O4),N4,O4),0) -> 0.03 | Q4: =IFERROR(Assumptions!$B$5+INDEX(Assumptions!$E$11:$E$19,MATCH(D4,Assumptions!$A$11:$A$19,0)),Assumptions!$B$5) -> 2027 | S4: =IF(ISBLANK(R4),Q4,R4) -> 2027 | T4: =L4*M4 -> 0 | U4: =P4*L4*M4 -> 0 | V4: =P4*G4*M4 -> 0 | W4: =P4*K4*M4 -> 0 | X4: =IFERROR(U4/(1+Assumptions!$B$6)^(S4-Assumptions!$B$5),0) -> 0 | Y4: 178000 | Z4: =IF(Y4=0,"",U4/Y4) -> 0 | AA4: =E4*Assumptions!$B$8*M4 -> 0 | AB4: Synthetic company. Stage D. Written down; no comps, stage default P(exit) applies to a nil value. | AC4: =IFERROR(INDEX(Assumptions!$F$11:$F$19,MATCH(D4,Assumptions!$A$11:$A$19,0)),0) -> 0 | AD4: =Y4*AC4 -> 0 | AE4: =Y4+AD4 -> 178000 | AF4: =IF(AE4=0,"",U4/AE4) -> 0
A5: Company 03 | B5: PC-03 | C5: Health Tech | D5: S4 | E5: 55490000 | F5: =COUNTIFS(Comps!$A$3:$A$700,$A5,Comps!$C$3:$C$700,"Exit",Comps!$G$3:$G$700,"Y") -> 5 | G5: {=IFERROR(MEDIAN(IF((Comps!$A$3:$A$700=$A5)*(Comps!$C$3:$C$700="Exit")*(Comps!$G$3:$G$700="Y"),Comps!$D$3:$D$700)),0)} -> 163660000 | H5: =COUNTIFS(Comps!$A$3:$A$700,$A5,Comps!$C$3:$C$700,"Private",Comps!$G$3:$G$700,"Y") -> 4 | I5: =IFERROR(AVERAGEIFS(Comps!$D$3:$D$700,Comps!$A$3:$A$700,$A5,Comps!$C$3:$C$700,"Private",Comps!$G$3:$G$700,"Y"),0) -> 62277500 | J5: =Assumptions!$B$7 -> 2.5 | K5: =I5*J5 -> 155693750 | L5: =IF(AND(G5>0,K5>0),(G5+K5)/2,MAX(G5,K5)) -> 159676875 | M5: 0.0779 | N5: =IFERROR(INDEX(Assumptions!$D$11:$D$19,MATCH(D5,Assumptions!$A$11:$A$19,0)),0) -> 0.3 | P5: =IFERROR(IF(ISBLANK(O5),N5,O5),0) -> 0.3 | Q5: =IFERROR(Assumptions!$B$5+INDEX(Assumptions!$E$11:$E$19,MATCH(D5,Assumptions!$A$11:$A$19,0)),Assumptions!$B$5) -> 2031 | S5: =IF(ISBLANK(R5),Q5,R5) -> 2031 | T5: =L5*M5 -> 12438829 | U5: =P5*L5*M5 -> 3731648.6 | V5: =P5*G5*M5 -> 3824734.2 | W5: =P5*K5*M5 -> 3638562.9 | X5: =IFERROR(U5/(1+Assumptions!$B$6)^(S5-Assumptions!$B$5),0) -> 1855288.9 | Y5: 3753000 | Z5: =IF(Y5=0,"",U5/Y5) -> 0.99431084 | AA5: =E5*Assumptions!$B$8*M5 -> 12968013 | AB5: Synthetic company. Stage S4. | AC5: =IFERROR(INDEX(Assumptions!$F$11:$F$19,MATCH(D5,Assumptions!$A$11:$A$19,0)),0) -> 1.5 | AD5: =Y5*AC5 -> 5629500 | AE5: =Y5+AD5 -> 9382500 | AF5: =IF(AE5=0,"",U5/AE5) -> 0.39772433
